Workbook

Sheet 水分&灰分
A1: 1110817
A2: 水分
A3: 樣品編號 | B3: 坩鍋編號 | C3: 坩鍋重量(g) | D3: 樣品重量(g) | E3: 坩鍋+樣品重量(g) | F3: 烘乾後坩鍋+樣品重量(g) | G3: 水分% | H3: 灰化後坩鍋+樣品重量(g) | I3: 灰分%
A4: A1-1 | B4: 347 | C4: 29.6849 | D4: 3.0169 | E4: =SUM(C4+D4) -> 32.7018 | F4: 30.4221 | G4: =(E4-F4)/D4*100 -> 75.564321 | H4: 29.7232 | I4: =(H4-C4)/D4*100 -> 1.2695151
A5: A1-2 | B5: 2 | C5: 29.5213 | D5: 3.0057 | E5: =SUM(C5+D5) -> 32.527 | F5: 30.2742 | G5: =(E5-F5)/D5*100 -> 74.950927 | H5: 29.5595 | I5: =(H5-C5)/D5*100 -> 1.2709186
A6: B1-1 | B6: 281 | C6: 26.8731 | D6: 3.0068 | E6: =SUM(C6+D6) -> 29.8799 | F6: 27.6409 | G6: =(E6-F6)/D6*100 -> 74.464547 | H6: 26.9119 | I6: =(H6-C6)/D6*100 -> 1.2904084
A7: B1-2 | B7: 295 | C7: 27.1332 | D7: 3.0029 | E7: =SUM(C7+D7) -> 30.1361 | F7: 27.8909 | G7: =(E7-F7)/D7*100 -> 74.767725 | H7: 27.1719 | I7: =(H7-C7)/D7*100 -> 1.2887542
A8: C1-1 | B8: 79 | C8: 28.271 | D8: 3.0057 | E8: =SUM(C8+D8) -> 31.2767 | F8: 29.0191 | G8: =(E8-F8)/D8*100 -> 75.110623 | H8: 28.3097 | I8: =(H8-C8)/D8*100 -> 1.2875536
A9: C1-2 | B9: 6 | C9: 29.6545 | D9: 2.9991 | E9: =SUM(C9+D9) -> 32.6536 | F9: 30.4076 | G9: =(E9-F9)/D9*100 -> 74.889133 | H9: 29.6929 | I9: =(H9-C9)/D9*100 -> 1.2803841
A10: D1-1 | B10: 240 | C10: 29.7987 | D10: 2.9982 | E10: =SUM(C10+D10) -> 32.7969 | F10: 30.5344 | G10: =(E10-F10)/D10*100 -> 75.461944 | H10: 29.8377 | I10: =(H10-C10)/D10*100 -> 1.3007805
A11: D1-2 | B11: 7 | C11: 27.0879 | D11: 2.9997 | E11: =SUM(C11+D11) -> 30.0876 | F11: 27.8134 | G11: =(E11-F11)/D11*100 -> 75.814248 | H11: 27.1264 | I11: =(H11-C11)/D11*100 -> 1.2834617
A12: E1-1 | B12: 284 | C12: 28.6309 | D12: 3.0077 | E12: =SUM(C12+D12) -> 31.6386 | F12: 29.3959 | G12: =(E12-F12)/D12*100 -> 74.565282 | H12: 28.6712 | I12: =(H12-C12)/D12*100 -> 1.3398943
A13: E1-2 | B13: 17 | C13: 29.7868 | D13: 3.0115 | E13: =SUM(C13+D13) -> 32.7983 | F13: 30.5431 | G13: =(E13-F13)/D13*100 -> 74.886269 | H13: 29.8276 | I13: =(H13-C13)/D13*100 -> 1.3548066
A15: 1110906
A16: 水分
A17: 樣品編號 | B17: 坩鍋編號 | C17: 坩鍋重量(g) | D17: 樣品重量(g) | E17: 坩鍋+樣品重量(g) | F17: 烘乾後坩鍋+樣品重量(g) | G17: 水分% | H17: 灰化後坩鍋+樣品重量(g) | I17: 灰分%
A18: A1-3 | B18: 79 | C18: 28.269 | D18: 3.0127 | E18: =SUM(C18+D18) -> 31.2817 | F18: 28.9964 | G18: =(E18-F18)/D18*100 -> 75.855545 | H18: 28.3073 | I18: =(H18-C18)/D18*100 -> 1.2712849
A19: A2-1 | B19: 281 | C19: 26.8704 | D19: 3.0173 | E19: =SUM(C19+D19) -> 29.8877 | F19: 27.6174 | G19: =(E19-F19)/D19*100 -> 75.242767 | H19: 26.9083 | I19: =(H19-C19)/D19*100 -> 1.2560899
A20: B1-3 | B20: 447 | C20: 21.4198 | D20: 3.0178 | E20: =SUM(C20+D20) -> 24.4376 | F20: 22.1507 | G20: =(E20-F20)/D20*100 -> 75.78037 | H20: 21.4582 | I20: =(H20-C20)/D20*100 -> 1.2724501
A21: B2-1 | B21: 16 | C21: 17.8159 | D21: 3.0056 | E21: =SUM(C21+D21) -> 20.8215 | F21: 18.5914 | G21: =(E21-F21)/D21*100 -> 74.198163 | H21: 17.8557 | I21: =(H21-C21)/D21*100 -> 1.3241948
A22: C1-3 | B22: 17 | C22: 29.7891 | D22: 3.0149 | E22: =SUM(C22+D22) -> 32.804 | F22: 30.5452 | G22: =(E22-F22)/D22*100 -> 74.921225 | H22: 29.8278 | I22: =(H22-C22)/D22*100 -> 1.2836247
A23: C2-1 | B23: 7 | C23: 27.0872 | D23: 2.957 | E23: =SUM(C23+D23) -> 30.0442 | F23: 27.847 | G23: =(E23-F23)/D23*100 -> 74.305039 | H23: 27.1264 | I23: =(H23-C23)/D23*100 -> 1.3256679
A24: D1-3 | B24: 240 | C24: 29.7965 | D24: 3.0233 | E24: =SUM(C24+D24) -> 32.8198 | F24: 30.5428 | G24: =(E24-F24)/D24*100 -> 75.315053 | H24: 29.8343 | I24: =(H24-C24)/D24*100 -> 1.2502894
A25: D2-1 | B25: 347 | C25: 29.6825 | D25: 3.0097 | E25: =SUM(C25+D25) -> 32.6922 | F25: 30.44 | G25: =(E25-F25)/D25*100 -> 74.831379 | H25: 29.7202 | I25: =(H25-C25)/D25*100 -> 1.2526165
A26: E1-3 | B26: 6 | C26: 29.6554 | D26: 2.9973 | E26: =SUM(C26+D26) -> 32.6527 | F26: 30.4037 | G26: =(E26-F26)/D26*100 -> 75.034197 | H26: 29.6933 | I26: =(H26-C26)/D26*100 -> 1.2644714
A27: E2-1 | B27: 284 | C27: 28.6308 | D27: 3.013 | E27: =SUM(C27+D27) -> 31.6438 | F27: 29.3782 | G27: =(E27-F27)/D27*100 -> 75.194159 | H27: 28.6685 | I27: =(H27-C27)/D27*100 -> 1.2512446
A29: 1110913
A30: 水分
A31: 樣品編號 | B31: 坩鍋編號 | C31: 坩鍋重量(g) | D31: 樣品重量(g) | E31: 坩鍋+樣品重量(g) | F31: 烘乾後坩鍋+樣品重量(g) | G31: 水分% | H31: 灰化後坩鍋+樣品重量(g) | I31: 灰分%
A32: A2-2 | B32: 284 | C32: 28.6356 | D32: 3.0161 | E32: =SUM(C32+D32) -> 31.6517 | F32: 29.3588 | G32: =(E32-F32)/D32*100 -> 76.022015 | H32: 28.6738 | I32: =(H32-C32)/D32*100 -> 1.2665363
A33: A3-1 | B33: 281 | C33: 26.8743 | D33: 3.0063 | E33: =SUM(C33+D33) -> 29.8806 | F33: 27.5985 | G33: =(E33-F33)/D33*100 -> 75.910588 | H33: 26.9119 | I33: =(H33-C33)/D33*100 -> 1.2507068
A34: B2-2 | B34: 447 | C34: 21.4257 | D34: 3.0356 | E34: =SUM(C34+D34) -> 24.4613 | F34: 22.2004 | G34: =(E34-F34)/D34*100 -> 74.47951 | H34: 21.4661 | I34: =(H34-C34)/D34*100 -> 1.3308736
A35: B3-1 | B35: 347 | C35: 29.687 | D35: 3.0086 | E35: =SUM(C35+D35) -> 32.6956 | F35: 30.4383 | G35: =(E35-F35)/D35*100 -> 75.028252 | H35: 29.724 | I35: =(H35-C35)/D35*100 -> 1.2298079
A36: C2-2 | B36: 16 | C36: 17.8209 | D36: 3.0239 | E36: =SUM(C36+D36) -> 20.8448 | F36: 18.603 | G36: =(E36-F36)/D36*100 -> 74.136049 | H36: 17.8601 | I36: =(H36-C36)/D36*100 -> 1.2963392
A37: C3-1 | B37: 7 | C37: 27.0929 | D37: 3.0051 | E37: =SUM(C37+D37) -> 30.098 | F37: 27.83 | G37: =(E37-F37)/D37*100 -> 75.471698 | H37: 27.1305 | I37: =(H37-C37)/D37*100 -> 1.2512063
A38: D2-2 | B38: 17 | C38: 29.7945 | D38: 3.0023 | E38: =SUM(C38+D38) -> 32.7968 | F38: 30.5778 | G38: =(E38-F38)/D38*100 -> 73.910002 | H38: 29.8334 | I38: =(H38-C38)/D38*100 -> 1.2956733
A39: D3-1 | B39: 6 | C39: 29.6609 | D39: 3.0265 | E39: =SUM(C39+D39) -> 32.6874 | F39: 30.4315 | G39: =(E39-F39)/D39*100 -> 74.538245 | H39: 29.7024 | I39: =(H39-C39)/D39*100 -> 1.3712209
A40: E2-2 | B40: 79 | C40: 28.2723 | D40: 3.0304 | E40: =SUM(C40+D40) -> 31.3027 | F40: 29.0247 | G40: =(E40-F40)/D40*100 -> 75.171595 | H40: 28.3109 | I40: =(H40-C40)/D40*100 -> 1.2737592
A41: E3-1 | B41: 240 | C41: 29.8017 | D41: 3.0244 | E41: =SUM(C41+D41) -> 32.8261 | F41: 30.5605 | G41: =(E41-F41)/D41*100 -> 74.910726 | H41: 29.8408 | I41: =(H41-C41)/D41*100 -> 1.2928184
A43: 1110920
...

Sheet 粗脂肪
A1: 1110817
A2: 粗脂肪
A3: 樣品編號 | B3: 脂肪瓶編號 | C3: 脂肪瓶重量(g) | D3: 樣品重量(g) | E3: 脂肪瓶+樣品重量(g) | F3: 萃取乾燥後脂肪瓶+脂肪重量(g) | G3: 粗脂肪%
A4: A1-1 | B4: 1 | C4: 109.1539 | D4: 3.0068 | E4: =SUM(C4+D4) -> 112.1607 | F4: 109.1758 | G4: =(F4-C4)/D4*100 -> 0.72834908
A5: A1-2 | B5: 2 | C5: 106.2282 | D5: 3.0038 | E5: =SUM(C5+D5) -> 109.232 | F5: 106.2488 | G5: =(F5-C5)/D5*100 -> 0.68579799
A6: B1-1 | B6: 3 | C6: 111.3458 | D6: 3.0081 | E6: =SUM(C6+D6) -> 114.3539 | F6: 111.3961 | G6: =(F6-C6)/D6*100 -> 1.6721519
A7: B1-2 | B7: 4 | C7: 106.1943 | D7: 3.0034 | E7: =SUM(C7+D7) -> 109.1977 | F7: 106.248 | G7: =(F7-C7)/D7*100 -> 1.7879736
A8: C1-1 | B8: 5 | C8: 109.9708 | D8: 3.0044 | E8: =SUM(C8+D8) -> 112.9752 | F8: 109.9983 | G8: =(F8-C8)/D8*100 -> 0.91532419
A9: C1-2 | B9: 6 | C9: 103.78 | D9: 3.0002 | E9: =SUM(C9+D9) -> 106.7802 | F9: 103.819 | G9: =(F9-C9)/D9*100 -> 1.2999133
A10: D1-1 | B10: 7 | C10: 107.6802 | D10: 3.0205 | E10: =SUM(C10+D10) -> 110.7007 | F10: 107.7061 | G10: =(F10-C10)/D10*100 -> 0.85747393
A11: D1-2 | B11: 8 | C11: 106.2914 | D11: 3.0147 | E11: =SUM(C11+D11) -> 109.3061 | F11: 106.3303 | G11: =(F11-C11)/D11*100 -> 1.290344
A12: E1-1 | B12: 9 | C12: 106.2777 | D12: 2.9977 | E12: =SUM(C12+D12) -> 109.2754 | F12: 106.3017 | G12: =(F12-C12)/D12*100 -> 0.8006138
A13: E1-2 | B13: 10 | C13: 106.1468 | D13: 3.0019 | E13: =SUM(C13+D13) -> 109.1487 | F13: 106.1781 | G13: =(F13-C13)/D13*100 -> 1.042673
A14: 空白 | B14: 0 | C14: 106.486 | D14: 0 | E14: =SUM(C14+D14) -> 106.486 | F14: 106.4886 | G14: 0
A16: 1110907
A17: 粗脂肪
A18: 樣品編號 | B18: 脂肪瓶編號 | C18: 脂肪瓶重量(g) | D18: 樣品重量(g) | E18: 脂肪瓶+樣品重量(g) | F18: 萃取乾燥後脂肪瓶+脂肪重量(g) | G18: 粗脂肪%
A19: A1-3 | B19: 1 | C19: 109.1525 | D19: 3.0303 | E19: =SUM(C19+D19) -> 112.1828 | F19: 109.1736 | G19: =(F19-C19)/D19*100 -> 0.6963007
A20: B1-3 | B20: 2 | C20: 106.2271 | D20: 3.0437 | E20: =SUM(C20+D20) -> 109.2708 | F20: 106.2489 | G20: =(F20-C20)/D20*100 -> 0.71623353
A21: C1-3 | B21: 3 | C21: 111.3427 | D21: 3.0199 | E21: =SUM(C21+D21) -> 114.3626 | F21: 111.3719 | G21: =(F21-C21)/D21*100 -> 0.96691943
A22: D1-3 | B22: 4 | C22: 106.1931 | D22: 2.9892 | E22: =SUM(C22+D22) -> 109.1823 | F22: 106.2233 | G22: =(F22-C22)/D22*100 -> 1.0103038
A23: E1-3 | B23: 5 | C23: 109.9706 | D23: 3.0053 | E23: =SUM(C23+D23) -> 112.9759 | F23: 109.9963 | G23: =(F23-C23)/D23*100 -> 0.85515589
A24: A2-1 | B24: 6 | C24: 103.7783 | D24: 3.045 | E24: =SUM(C24+D24) -> 106.8233 | F24: 103.8012 | G24: =(F24-C24)/D24*100 -> 0.75205255
A25: B2-1 | B25: 7 | C25: 107.6791 | D25: 2.9994 | E25: =SUM(C25+D25) -> 110.6785 | F25: 107.712 | G25: =(F25-C25)/D25*100 -> 1.096886
A26: C2-1 | B26: 8 | C26: 106.29 | D26: 3.0289 | E26: =SUM(C26+D26) -> 109.3189 | F26: 106.3324 | G26: =(F26-C26)/D26*100 -> 1.3998481
A27: D2-1 | B27: 9 | C27: 106.2762 | D27: 3.0322 | E27: =SUM(C27+D27) -> 109.3084 | F27: 106.3137 | G27: =(F27-C27)/D27*100 -> 1.2367258
A28: E2-1 | B28: 10 | C28: 106.1436 | D28: 3.0284 | E28: =SUM(C28+D28) -> 109.172 | F28: 106.1656 | G28: =(F28-C28)/D28*100 -> 0.72645621
A29: 空白 | B29: 0 | C29: 106.4838 | D29: 0 | E29: =SUM(C29+D29) -> 106.4838 | F29: 106.4836 | G29: 0
A31: 1110915
A32: 粗脂肪
A33: 樣品編號 | B33: 脂肪瓶編號 | C33: 脂肪瓶重量(g) | D33: 樣品重量(g) | E33: 脂肪瓶+樣品重量(g) | F33: 萃取乾燥後脂肪瓶+脂肪重量(g) | G33: 粗脂肪%
A34: A2-2 | B34: 1 | C34: 109.1525 | D34: 2.9903 | E34: =SUM(C34+D34) -> 112.1428 | F34: 109.1784 | G34: =(F34-C34)/D34*100 -> 0.86613383
A35: B2-2 | B35: 2 | C35: 106.2265 | D35: 3.0136 | E35: =SUM(C35+D35) -> 109.2401 | F35: 106.271 | G35: =(F35-C35)/D35*100 -> 1.4766392
A36: C2-2 | B36: 3 | C36: 111.3416 | D36: 2.9819 | E36: =SUM(C36+D36) -> 114.3235 | F36: 111.3714 | G36: =(F36-C36)/D36*100 -> 0.99936282
A37: D2-2 | B37: 4 | C37: 106.193 | D37: 3.0366 | E37: =SUM(C37+D37) -> 109.2296 | F37: 106.243 | G37: =(F37-C37)/D37*100 -> 1.6465784
A38: E2-2 | B38: 5 | C38: 109.97 | D38: 3.0484 | E38: =SUM(C38+D38) -> 113.0184 | F38: 110.0101 | G38: =(F38-C38)/D38*100 -> 1.3154442
A39: A3-1 | B39: 6 | C39: 103.7783 | D39: 3.0149 | E39: =SUM(C39+D39) -> 106.7932 | F39: 103.8111 | G39: =(F39-C39)/D39*100 -> 1.0879299
A40: B3-1 | B40: 7 | C40: 107.6785 | D40: 3.0234 | E40: =SUM(C40+D40) -> 110.7019 | F40: 107.7242 | G40: =(F40-C40)/D40*100 -> 1.5115433
A41: C3-1 | B41: 8 | C41: 106.2903 | D41: 3.0174 | E41: =SUM(C41+D41) -> 109.3077 | F41: 106.3261 | G41: =(F41-C41)/D41*100 -> 1.1864519
A42: D3-1 | B42: 9 | C42: 106.2764 | D42: 3.0111 | E42: =SUM(C42+D42) -> 109.2875 | F42: 106.3142 | G42: =(F42-C42)/D42*100 -> 1.2553552
...

Sheet 依分析日期彙整之總表
A2: Date | B2: Sample No. | C2: Moisture | D2: Protein | E2: Fat | F2: Ash
A3: 1110817 | B3: A1-1 | C3: 75.564321 | D3: 21.25 | E3: 0.72834908 | F3: 1.2695151
A4: 1110817 | B4: A1-2 | C4: 74.950927 | D4: 20.94 | E4: 0.68579799 | F4: 1.2709186
A5: 1110817 | B5: B1-1 | C5: 74.464547 | D5: 21.97 | E5: 1.6721519 | F5: 1.2904084
A6: 1110817 | B6: B1-2 | C6: 74.767725 | D6: 22.13 | E6: 1.7879736 | F6: 1.2887542
A7: 1110817 | B7: C1-1 | C7: 75.110623 | D7: 22.23 | E7: 0.91532419 | F7: 1.2875536
A8: 1110817 | B8: C1-2 | C8: 74.889133 | D8: 22.09 | E8: 1.2999133 | F8: 1.2803841
A9: 1110817 | B9: D1-1 | C9: 75.461944 | D9: 22.3 | E9: 0.85747393 | F9: 1.3007805
A10: 1110817 | B10: D1-2 | C10: 75.814248 | D10: 21.14 | E10: 1.290344 | F10: 1.2834617
A11: 1110817 | B11: E1-1 | C11: 74.565282 | D11: 22.98 | E11: 0.8006138 | F11: 1.3398943
A12: 1110817 | B12: E1-2 | C12: 74.886269 | D12: 22.94 | E12: 1.042673 | F12: 1.3548066
A13: 1110906 | B13: A1-3 | C13: 75.855545 | D13: 21.1 | E13: 0.6963007 | F13: 1.2712849
A14: 1110906 | B14: A2-1 | C14: 75.242767 | D14: 21.15 | E14: 0.71623353 | F14: 1.2560899
... A47: 1110927 | B47: E3-3 | C47: 75.171776 | D47: 21.65 | E47: 1.225555 | F47: 1.4386348

Sheet 工作表1
B1: 水分% | C1: 平均% | D1: 灰分% | E1: 平均% | F1: 粗脂肪% | G1: 平均% | J1: 水分% | K1: 平均% | L1: 灰分% | M1: 平均% | N1: 粗脂肪% | O1: 平均% | R1: 水分% | S1: 平均% | T1: 灰分% | U1: 平均% | V1: 粗脂肪% | W1: 平均%
A2: A1-1 | B2: 75.564321 | C2: =AVERAGE(B2:B4) -> 75.456931 | D2: 0.012695151 | E2: =AVERAGE(D2:D4) -> 0.012705728 | F2: 0.0072834908 | G2: =AVERAGE(F2:F4) -> 0.0070348259 | I2: A2-1 | J2: 75.242767 | K2: =AVERAGE(J2:J4) -> 75.395551 | L2: 0.012560899 | M2: =AVERAGE(L2:L4) -> 0.42731959 | N2: 0.0075205255 | O2: =AVERAGE(N2:N4) -> 0.28084862 | Q2: A3-1 | R2: 75.910588 | S2: =AVERAGE(R2:R4) -> 75.732235 | T2: 0.012507068 | U2: =AVERAGE(T2:T4) -> 0.82742043 | V2: 0.010879299 | W2: =AVERAGE(V2:V4) -> 0.61354237
A3: A1-2 | B3: 74.950927 | D3: 0.012709186 | F3: 0.0068579799 | I3: A2-2 | J3: 76.022015 | L3: 0.012665363 | N3: 0.0086613383 | Q3: A3-2 | R3: ='水分&灰分'!G51 -> 75.12812 | T3: ='水分&灰分'!I51 -> 1.2678869 | V3: =粗脂肪!G54 -> 0.9233733
A4: A1-3 | B4: 75.855545 | D4: 0.012712849 | F4: 0.006963007 | I4: A2-3 | J4: ='水分&灰分'!G46 -> 74.92187 | L4: ='水分&灰分'!I46 -> 1.2567325 | N4: =粗脂肪!G49 -> 0.826364 | Q4: A3-3 | R4: ='水分&灰分'!G60 -> 76.157998 | T4: ='水分&灰分'!I60 -> 1.2018674 | V4: =粗脂肪!G64 -> 0.9063745
A5: B1-1 | B5: 74.464547 | C5: =AVERAGE(B5:B7) -> 75.004214 | D5: 0.012904084 | E5: =AVERAGE(D5:D7) -> 0.012838709 | F5: 0.016721519 | G5: =AVERAGE(F5:F7) -> 0.013921197 | I5: B2-1 | J5: 74.198163 | K5: =AVERAGE(J5:J7) -> 74.556731 | L5: 0.013241948 | M5: =AVERAGE(L5:L7) -> 0.43001953 | N5: 0.01096886 | O5: =AVERAGE(N5:N7) -> 0.011845084 | Q5: B3-1 | R5: 75.028252 | S5: =AVERAGE(R5:R7) -> 75.50569 | T5: 0.012298079 | U5: =AVERAGE(T5:T7) -> 0.82895776 | V5: 0.015115433 | W5: =AVERAGE(V5:V7) -> 0.68685076
A6: B1-2 | B6: 74.767725 | D6: 0.012887542 | F6: 0.017879736 | I6: B2-2 | J6: 74.47951 | L6: 0.013308736 | N6: 0.014766392 | Q6: B3-2 | R6: ='水分&灰分'!G52 -> 75.974935 | T6: ='水分&灰分'!I52 -> 1.2332511 | V6: =粗脂肪!G55 -> 1.049799
A7: B1-3 | B7: 75.78037 | D7: 0.012724501 | F7: 0.0071623353 | I7: B2-3 | J7: ='水分&灰分'!G47 -> 74.992519 | L7: ='水分&灰分'!I47 -> 1.2635079 | N7: 0.0098 | Q7: B3-3 | R7: ='水分&灰分'!G61 -> 75.513881 | T7: ='水分&灰分'!I61 -> 1.2413241 | V7: =粗脂肪!G65 -> 0.99563784
A8: C1-1 | B8: 75.110623 | C8: =AVERAGE(B8:B10) -> 74.97366 | D8: 0.012875536 | E8: =AVERAGE(D8:D10) -> 0.012838541 | F8: 0.0091532419 | G8: =AVERAGE(F8:F10) -> 0.01060719 | I8: C2-1 | J8: 74.305039 | K8: =AVERAGE(J8:J10) -> 74.336904 | L8: 0.013256679 | M8: =AVERAGE(L8:L10) -> 0.43856167 | N8: 0.013998481 | O8: =AVERAGE(N8:N10) -> 0.50124849 | Q8: C3-1 | R8: 75.471698 | S8: =AVERAGE(R8:R10) -> 74.576632 | T8: 0.012512063 | U8: =AVERAGE(T8:T10) -> 0.88547022 | V8: 0.011864519 | W8: =AVERAGE(V8:V10) -> 0.67976828
A9: C1-2 | B9: 74.889133 | D9: 0.012803841 | F9: 0.012999133 | I9: C2-2 | J9: 74.136049 | L9: 0.012963392 | N9: 0.0099936282 | Q9: C3-2 | R9: ='水分&灰分'!G53 -> 74.411324 | T9: ='水分&灰分'!I53 -> 1.325562 | V9: =粗脂肪!G56 -> 0.98680932
A10: C1-3 | B10: 74.921225 | D10: 0.012836247 | F10: 0.0096691943 | I10: C2-3 | J10: ='水分&灰分'!G48 -> 74.569624 | L10: ='水分&灰分'!I48 -> 1.2894649 | N10: =粗脂肪!G51 -> 1.4797534 | Q10: C3-3 | R10: ='水分&灰分'!G62 -> 73.846873 | T10: ='水分&灰分'!I62 -> 1.3183366 | V10: =粗脂肪!G66 -> 1.040631
A11: D1-1 | B11: 75.461944 | C11: =AVERAGE(B11:B13) -> 75.530415 | D11: 0.013007805 | E11: =AVERAGE(D11:D13) -> 0.012781772 | F11: 0.0085747393 | G11: =AVERAGE(F11:F13) -> 0.010527072 | I11: D2-1 | J11: 74.831379 | K11: =AVERAGE(J11:J13) -> 74.725046 | L11: 0.012526165 | M11: =AVERAGE(L11:L13) -> 0.42507787 | N11: 0.012367258 | O11: =AVERAGE(N11:N13) -> 0.013611014 | Q11: D3-1 | R11: 74.538245 | S11: =AVERAGE(R11:R13) -> 74.645449 | T11: 0.013712209 | U11: =AVERAGE(T11:T13) -> 0.86184734 | V11: 0.012553552 | W11: =AVERAGE(V11:V13) -> 1.0140513
A12: D1-2 | B12: 75.814248 | D12: 0.012834617 | F12: 0.01290344 | I12: D2-2 | J12: 73.910002 | L12: 0.012956733 | N12: 0.016465784 | Q12: D3-2 | R12: ='水分&灰分'!G54 -> 75.625437 | T12: ='水分&灰分'!I54 -> 1.2458776 | V12: =粗脂肪!G57 -> 1.6416821
A13: D1-3 | B13: 75.315053 | D13: 0.012502894 | F13: 0.010103038 | I13: D2-3 | J13: ='水分&灰分'!G49 -> 75.433757 | L13: ='水分&灰分'!I49 -> 1.2497507 | N13: 0.012 | Q13: D3-3 | R13: ='水分&灰分'!G63 -> 73.772665 | T13: ='水分&灰分'!I63 -> 1.3259522 | V13: =粗脂肪!G67 -> 1.3879181
A14: E1-1 | B14: 74.565282 | C14: =AVERAGE(B14:B16) -> 74.828583 | D14: 0.013398943 | E14: =AVERAGE(D14:D16) -> 0.013197241 | F14: 0.008006138 | G14: =AVERAGE(F14:F16) -> 0.0089948089 | I14: E2-1 | J14: 75.194159 | K14: =AVERAGE(J14:J16) -> 75.051601 | L14: 0.012512446 | M14: =AVERAGE(L14:L16) -> 0.42034944 | N14: 0.0072645621 | O14: =AVERAGE(N14:N16) -> 0.41118338 | Q14: E3-1 | R14: 74.910726 | S14: =AVERAGE(R14:R16) -> 75.090924 | T14: 0.012928184 | U14: =AVERAGE(T14:T16) -> 0.8271541 | V14: 0.012689508 | W14: =AVERAGE(V14:V16) -> 0.85314981
A15: E1-2 | B15: 74.886269 | D15: 0.013548066 | F15: 0.01042673 | I15: E2-2 | J15: 75.171595 | L15: 0.012737592 | N15: 0.013154442 | Q15: E3-2 | R15: ='水分&灰分'!G55 -> 75.190269 | T15: ='水分&灰分'!I55 -> 1.2429792 | V15: =粗脂肪!G58 -> 1.1081251
A16: E1-3 | B16: 75.034197 | D16: 0.012644714 | F16: 0.0085515589 | I16: E2-3 | J16: ='水分&灰分'!G50 -> 74.789051 | L16: ='水分&灰分'!I50 -> 1.2357983 | N16: =粗脂肪!G53 -> 1.2131311 | Q16: E3-3 | R16: ='水分&灰分'!G64 -> 75.171776 | T16: ='水分&灰分'!I64 -> 1.225555 | V16: =粗脂肪!G68 -> 1.4386348
